Workbook

Sheet Guiding Sheet

Sheet Development Costs Non Recurrent
A1: Section | B1: Details
A2: Initial Design | B2: Components | C2: Description | D2: Count | E2: Employment | F2: Duration (days) | G2: Company Cost (per day) | H2: Total Cost ($)
A3: Preliminary Concept | B3: Blockchain Engineer | C3: Engineer focused on blockchain system design | D3: 2 people | E3: full-time | F3: 60 | G3: 800 | H3: 96000
B4: Senior Systems Engineer | C4: Senior engineer for systems integration | D4: 1 person | E4: full-time | F4: 60 | G4: 1000 | H4: 60000
G5: Subtotal | H5: =SUM(H3:H4) -> 156000
A6: Assemble, Integrate, and Test | B6: Components | C6: Description | D6: Count | E6: Employment | F6: Duration (days) | G6: Company Cost (per day) | H6: Total Cost ($)
A7: Hardware | B7: IoT Sensors | C7: Essential components for water quality measurement | D7: 10 units | E7: - | F7: - | G7: $50 per unit | H7: 500
A8: People | B8: Senior Hardware Engineer | C8: Engineer for hardware setup and testing | D8: 1 person | E8: full-time | F8: 60 | G8: 800 | H8: 48000
B9: Senior Software Engineer | C9: Engineer for blockchain software development | D9: 1 person | E9: full-time | F9: 60 | G9: 800 | H9: 48000
B10: Networking Equipment | C10: Routers and related networking hardware for IoT integration | D10: 1 unit | E10: - | F10: - | G10: 200 | H10: 200
B11: Development Kits | C11: Tools for IoT device development | D11: - | E11: - | F11: - | G11: - | H11: 2000
B12: Laptop | C12: For software development and testing | D12: 4 units | E12: - | F12: - | G12: $1,000 per unit | H12: 4000
G13: Subtotal | H13: =SUM(H7:H12) -> 102700
A14: Prototype | B14: Components | C14: Description | D14: Count | E14: Employment | F14: Duration (days) | G14: Company Cost (per day) | H14: Total Cost ($)
A15: Proof of Concept | B15: Senior Engineer | C15: Supervision and development of prototype | D15: 1 person | E15: full-time | F15: 30 | G15: 1000 | H15: 30000
B16: Engineer | C16: Assistance in prototype development | D16: 1 person | E16: full-time | F16: 30 | G16: 800 | H16: 24000
G17: Subtotal | H17: =SUM(H15:H16) -> 54000
A18: Verification and Validation | B18: Components | C18: Description | D18: Count | E18: Employment | F18: Duration (days) | G18: Company Cost (per day) | H18: Total Cost ($)
A19: System level total integration | B19: Senior Systems Engineer | C19: Integration testing and validation | D19: 1 person | E19: full-time | F19: 30 | G19: 1000 | H19: 30000
B20: Systems Engineer | C20: Assistance in system validation | D20: 1 person | E20: full-time | F20: 30 | G20: 800 | H20: 24000
G21: Subtotal | H21: =SUM(H19:H20) -> 54000
G22: Total Development Cost | H22: =SUM(H5+H13+H17+H21) -> 366700
A24: Comments
A26: Company cost per day is assumed based on industry averages for engineering roles.
A27: For hardware components, an estimate is given based on bulk purchase of units for a prototype. This may vary based on actual unit costs at the time of procurement.
A28: Development kits, laptops, and networking equipment are estimated based on current market prices for mid-to-high range equipment.
A29: This table does not account for indirect costs such as utilities, rent, and administrative expenses.
A30: The costs for people include estimated employment costs but may vary based on the actual salaries, benefits, and taxes applicable.
A31: Duration for the initial design and assemble, integrate, and test phases assumes a two-month period, which is typical for the initial stages of a complex project like AquaChain. The prototype and verification/validation phases are estimated at one month each, for rapid development and testing cycles.

Sheet Production Costs Recurrent Cost
A1: Recurring Monthly Production Expenses
B2: Components | C2: Total Cost
A3: Indirect Cost | B3: Rent (WFH) | C3: 0
B4: Utilities (Electricity, Water, Internet, etc) - WFH | C4: 0
B5: Technology Licenses (Zoom, Microsoft, GitHub, etc) | C5: 1000
B6: Advertising | C6: 200
B7: Employee WFH office stipends | C7: 250
B8: Insurance, Legal and Administrative Fees | C8: 500
B9: Hardware costs (computers, IT hardware) | C9: 1000
B10: Travel costs (in person meetings) | C10: 1000
A11: Direct Cost
B12: IoT Sensors : Company Partnership/Tieup | C12: 5000
B13: Blockchain Engineer | C13: 24000
B14: Senior Systems Engineer | C14: 30000
B15: Senior Hardware Engineer | C15: 24000
B16: Senior Software Engineer | C16: 24000
B17: Product Manager | C17: 30000
B20: Total Production costs | C20: =SUM(C3:C19) -> 140950
C22: =SUM(C3:C10) -> 3950 | D22: =SUM(C11:C19) -> 137000
B24: Engineers | C24: 102000
B25: Product Manager | C25: 30000
B26: IoT Sensors | C26: 5000
B27: Indirect Cost | C27: 3950

Sheet Sales Forecast
A1: Phased Growth Approach
A2: Year | B2: Clients in Pipeline | C2: Client Growth (%) | D2: Conversion Rate | E2: Price per Unit ($) | F2: Annual Units Sold | G2: Revenue | I2: =A2 -> Year | J2: =G2 -> Revenue
A3: 2024 | B3: 10000 | C3: 0 | D3: 0.1 | E3: 174.48 | F3: =(B3*D3) -> 1000 | G3: =(E3*F3) -> 174480 | I3: =A3 -> 2024 | J3: =G3 -> 174480
A4: 2025 | B4: 13000 | C4: 0.3 | D4: 0.15 | E4: 174.48 | F4: =(B4*D4) -> 1950 | G4: =(F4*E4) -> 340236 | I4: =A4 -> 2025 | J4: =G4 -> 340236
A5: 2026 | B5: 15600 | C5: 0.2 | D5: 0.2 | E5: 191.928 | F5: =(B5*D5) -> 3120 | G5: =(F5*E5) -> 598815.36 | I5: =A5 -> 2026 | J5: =G5 -> 598815.36
A6: 2027 | B6: 17940 | C6: 0.15 | D6: 0.2 | E6: 191.928 | F6: =(B6*D6) -> 3588 | G6: =(F6*E6) -> 688637.66 | I6: =A6 -> 2027 | J6: =G6 -> 688637.66
A7: 2028 | B7: 19734 | C7: 0.1 | D7: 0.3 | E7: 211.123 | F7: =(B7*D7) -> 5920.2 | G7: =(F7*E7) -> 1249890.4 | I7: =A7 -> 2028 | J7: =G7 -> 1249890.4
A8: 2029 | B8: 22577.2 | C8: 0.1 | D8: 0.3 | E8: 211.123 | F8: =(B8*D8) -> 6773.16 | G8: =(F8*E8) -> 1429969.9 | I8: =A8 -> 2029 | J8: =G8 -> 1429969.9
A9: 2030 | B9: 25018 | C9: 0.1 | D9: 0.3 | E9: 211.123 | F9: =(B9*D9) -> 7505.4 | G9: =(F9*E9) -> 1584562.6 | I9: =A9 -> 2030 | J9: =G9 -> 1584562.6
A10: 2031 | B10: 27458.8 | C10: 0.1 | D10: 0.3 | E10: 211.123 | F10: =(B10*D10) -> 8237.64 | G10: =(F10*E10) -> 1739155.3 | I10: =A10 -> 2031 | J10: =G10 -> 1739155.3
A11: 2032 | B11: 29899.6 | C11: 0.1 | D11: 0.3 | E11: 211.123 | F11: =(B11*D11) -> 8969.88 | G11: =(F11*E11) -> 1893748 | I11: =A11 -> 2032 | J11: =G11 -> 1893748
A12: 2033 | B12: 32340.4 | C12: 0.1 | D12: 0.3 | E12: 211.123 | F12: =(B12*D12) -> 9702.12 | G12: =(F12*E12) -> 2048340.7 | I12: =A12 -> 2033 | J12: =G12 -> 2048340.7
G13: =SUM(G3:G12) -> 11747836
A14: Year 2024
A15: Month | B15: Units Sold | C15: Monthly Revenue | D15: Cumulative Revenue
A16: January | B16: 84 | C16: =B16*174.48 -> 14656.32 | D16: 14656.32
A17: February | B17: 76 | C17: =B17*174.48 -> 13260.48 | D17: =(D16+C17) -> 27916.8
A18: March | B18: 90 | C18: =B18*174.48 -> 15703.2 | D18: =(D17+C18) -> 43620 | E18: Q1: January to March | F18: =SUM(B16:B18) -> 250
A19: April | B19: 96 | C19: =B19*174.48 -> 16750.08 | D19: =(D18+C19) -> 60370.08 | E19: Q2: April to June | F19: =SUM(B19:B21) -> 246
A20: May | B20: 80 | C20: =B20*174.48 -> 13958.4 | D20: =(D19+C20) -> 74328.48 | E20: Q3: July to September | F20: =SUM(B22:B24) -> 262
A21: June | B21: 70 | C21: =B21*174.48 -> 12213.6 | D21: =(D20+C21) -> 86542.08 | E21: Q4: October to December | F21: =SUM(B25:B27) -> 242
A22: July | B22: 86 | C22: =B22*174.48 -> 15005.28 | D22: =(D21+C22) -> 101547.36
A23: August | B23: 96 | C23: =B23*174.48 -> 16750.08 | D23: =(D22+C23) -> 118297.44
A24: September | B24: 80 | C24: =B24*174.48 -> 13958.4 | D24: =(D23+C24) -> 132255.84
A25: October | B25: 76 | C25: =B25*174.48 -> 13260.48 | D25: =(D24+C25) -> 145516.32
A26: November | B26: 86 | C26: =B26*174.48 -> 15005.28 | D26: =(D25+C26) -> 160521.6
A27: December | B27: 80 | C27: =B27*174.48 -> 13958.4 | D27: =(D26+C27) -> 174480
A29: Comments
A31: This approach acknowledges that the initial years might see a higher growth rate in potential clients as there's more opportunity for new users.
A32: However, as the market becomes more saturated with AquaChain, the growth rate is likely to slow down in later years
A34: In a phased growth approach for AquaChain, we assume a higher initial growth rate followed by a stagnation for a few reasons:
A36: 1. Market Saturation
A37: 2. Early Adopters
A38: 3. Marketing and Sales Efforts
A39: 4. Competition
A41: Reasons for 5% increase in conversion ration annually
A43: 1. Industry Standard
A44: 2. Conservative estimate
A45: 3. Marketing & Sales Strategy
... A51: Orange County Water District (OCWD)

Sheet Master Production Schedule
B2: Month | C2: 2024 | D2: 2025 | E2: 2026 | F2: 2027 | G2: 2028 | H2: 2029 | I2: 2030 | J2: 2031 | K2: 2032 | L2: 2033
B3: January | C3: ='Sales Forecast'!B16 -> 84 | D3: =C3*$C$16 -> 163.8 | E3: =D3*D$16 -> 262.08 | F3: =E3*E$16 -> 301.392 | G3: =F3*F$16 -> 497.2968 | H3: =G3*G$16 -> 568.94544 | I3: =H3*H$16 -> 630.4536 | J3: =I3*I$16 -> 691.96176 | K3: =J3*J$16 -> 753.46992 | L3: =K3*K$16 -> 814.97808
B4: February | C4: ='Sales Forecast'!B17 -> 76 | D4: =C4*$C$16 -> 148.2 | E4: =D4*$D$16 -> 237.12 | F4: =E4*E$16 -> 272.688 | G4: =F4*F$16 -> 449.9352 | H4: =G4*G$16 -> 514.76016 | I4: =H4*H$16 -> 570.4104 | J4: =I4*I$16 -> 626.06064 | K4: =J4*J$16 -> 681.71088 | L4: =K4*K$16 -> 737.36112
B5: March | C5: ='Sales Forecast'!B18 -> 90 | D5: =C5*$C$16 -> 175.5 | E5: =D5*$D$16 -> 280.8 | F5: =E5*E$16 -> 322.92 | G5: =F5*F$16 -> 532.818 | H5: =G5*G$16 -> 609.5844 | I5: =H5*H$16 -> 675.486 | J5: =I5*I$16 -> 741.3876 | K5: =J5*J$16 -> 807.2892 | L5: =K5*K$16 -> 873.1908
B6: April | C6: ='Sales Forecast'!B19 -> 96 | D6: =C6*$C$16 -> 187.2 | E6: =D6*$D$16 -> 299.52 | F6: =E6*E$16 -> 344.448 | G6: =F6*F$16 -> 568.3392 | H6: =G6*G$16 -> 650.22336 | I6: =H6*H$16 -> 720.5184 | J6: =I6*I$16 -> 790.81344 | K6: =J6*J$16 -> 861.10848 | L6: =K6*K$16 -> 931.40352
B7: May | C7: ='Sales Forecast'!B20 -> 80 | D7: =C7*$C$16 -> 156 | E7: =D7*$D$16 -> 249.6 | F7: =E7*E$16 -> 287.04 | G7: =F7*F$16 -> 473.616 | H7: =G7*G$16 -> 541.8528 | I7: =H7*H$16 -> 600.432 | J7: =I7*I$16 -> 659.0112 | K7: =J7*J$16 -> 717.5904 | L7: =K7*K$16 -> 776.1696
B8: June | C8: ='Sales Forecast'!B21 -> 70 | D8: =C8*$C$16 -> 136.5 | E8: =D8*$D$16 -> 218.4 | F8: =E8*E$16 -> 251.16 | G8: =F8*F$16 -> 414.414 | H8: =G8*G$16 -> 474.1212 | I8: =H8*H$16 -> 525.378 | J8: =I8*I$16 -> 576.6348 | K8: =J8*J$16 -> 627.8916 | L8: =K8*K$16 -> 679.1484
B9: July | C9: ='Sales Forecast'!B22 -> 86 | D9: =C9*$C$16 -> 167.7 | E9: =D9*$D$16 -> 268.32 | F9: =E9*E$16 -> 308.568 | G9: =F9*F$16 -> 509.1372 | H9: =G9*G$16 -> 582.49176 | I9: =H9*H$16 -> 645.4644 | J9: =I9*I$16 -> 708.43704 | K9: =J9*J$16 -> 771.40968 | L9: =K9*K$16 -> 834.38232
B10: August | C10: ='Sales Forecast'!B23 -> 96 | D10: =C10*$C$16 -> 187.2 | E10: =D10*$D$16 -> 299.52 | F10: =E10*E$16 -> 344.448 | G10: =F10*F$16 -> 568.3392 | H10: =G10*G$16 -> 650.22336 | I10: =H10*H$16 -> 720.5184 | J10: =I10*I$16 -> 790.81344 | K10: =J10*J$16 -> 861.10848 | L10: =K10*K$16 -> 931.40352
B11: September | C11: ='Sales Forecast'!B24 -> 80 | D11: =C11*$C$16 -> 156 | E11: =D11*$D$16 -> 249.6 | F11: =E11*E$16 -> 287.04 | G11: =F11*F$16 -> 473.616 | H11: =G11*G$16 -> 541.8528 | I11: =H11*H$16 -> 600.432 | J11: =I11*I$16 -> 659.0112 | K11: =J11*J$16 -> 717.5904 | L11: =K11*K$16 -> 776.1696
B12: October | C12: ='Sales Forecast'!B25 -> 76 | D12: =C12*$C$16 -> 148.2 | E12: =D12*$D$16 -> 237.12 | F12: =E12*E$16 -> 272.688 | G12: =F12*F$16 -> 449.9352 | H12: =G12*G$16 -> 514.76016 | I12: =H12*H$16 -> 570.4104 | J12: =I12*I$16 -> 626.06064 | K12: =J12*J$16 -> 681.71088 | L12: =K12*K$16 -> 737.36112
B13: November | C13: ='Sales Forecast'!B26 -> 86 | D13: =C13*$C$16 -> 167.7 | E13: =D13*$D$16 -> 268.32 | F13: =E13*E$16 -> 308.568 | G13: =F13*F$16 -> 509.1372 | H13: =G13*G$16 -> 582.49176 | I13: =H13*H$16 -> 645.4644 | J13: =I13*I$16 -> 708.43704 | K13: =J13*J$16 -> 771.40968 | L13: =K13*K$16 -> 834.38232
B14: December | C14: ='Sales Forecast'!B27 -> 80 | D14: =C14*$C$16 -> 156 | E14: =D14*$D$16 -> 249.6 | F14: =E14*E$16 -> 287.04 | G14: =F14*F$16 -> 473.616 | H14: =G14*G$16 -> 541.8528 | I14: =H14*H$16 -> 600.432 | J14: =I14*I$16 -> 659.0112 | K14: =J14*J$16 -> 717.5904 | L14: =K14*K$16 -> 776.1696
B15: Total Units | C15: 1000 | D15: 1950 | E15: 3120 | F15: 3588 | G15: 5920.2 | H15: 6773.16 | I15: 7505.4 | J15: 8237.64 | K15: 8969.88 | L15: 9702.12
B16: Ratios | C16: =D15/C15 -> 1.95 | D16: =E15/D15 -> 1.6 | E16: =F15/E15 -> 1.15 | F16: =G15/F15 -> 1.65 | G16: =H15/G15 -> 1.1440762 | H16: =I15/H15 -> 1.1081091 | I16: =J15/I15 -> 1.0975618 | J16: =K15/J15 -> 1.0888895 | K16: =L15/K15 -> 1.0816332

Sheet BOM
A2: Item # | B2: Assembly Group | C2: Item | D2: Unit Cost | E2: Quantity | F2: Total Cost | G2: LT (Days)
A3: 1 | B3: Housing | C3: Steel Metal | D3: 11.5 | E3: 1 | F3: =D3*E3 -> 11.5 | G3: 5
A4: 2 | B4: Plumbing | C4: Seals | D4: 1 | E4: 2 | F4: =D4*E4 -> 2 | G4: 3
A5: 3 | C5: Clamps | D5: 1 | E5: 1 | F5: =D5*E5 -> 1 | G5: 3
A6: 4 | B6: Fasteners | C6: Screws | D6: 0.1 | E6: 8 | F6: =D6*E6 -> 0.8 | G6: 3
A7: 5 | C7: Nuts | D7: 0.1 | E7: 8 | F7: =D7*E7 -> 0.8 | G7: 3
A8: 6 | C8: Bolts | D8: 0.1 | E8: 8 | F8: =D8*E8 -> 0.8 | G8: 3
A9: 7 | B9: Electronics | C9: Circuit Board | D9: 10 | E9: 1 | F9: =D9*E9 -> 10 | G9: 7
A10: 8 | C10: Wires | D10: 1 | E10: 4 | F10: =D10*E10 -> 4 | G10: 3
A11: 9 | C11: Microcontroller | D11: 20 | E11: 1 | F11: =D11*E11 -> 20 | G11: 7
A12: 10 | C12: LCD Display | D12: 10 | E12: 1 | F12: =D12*E12 -> 10 | G12: 5
A13: 11 | C13: Flow meter | D13: 10 | E13: 1 | F13: =D13*E13 -> 10 | G13: 7
A14: 12 | C14: Electrochemical Sensor | D14: 10 | E14: 1 | F14: =D14*E14 -> 10 | G14: 7
A15: 13 | C15: Antenna | D15: 10 | E15: 1 | F15: =D15*E15 -> 10 | G15: 5
A16: 14 | C16: AC Power Cord | D16: 5 | E16: 1 | F16: =D16*E16 -> 5 | G16: 3
A17: 15 | C17: AC Power Extensions | D17: 2 | E17: 1 | F17: =D17*E17 -> 2 | G17: 3
F18: =SUM(F3:F17) -> 97.9

Sheet Pricing Model
A1: Monthly Product Expenses | B1: Total Cost
A2: Actual Product Price | E2: Salary
A3: Marketing | B3: 200 | C3: 200 | E3: Blockchain Engineer | F3: 24000
A4: Contractual Company Cost for Sensors | B4: 5000 | C4: 5000 | E4: Senior Systems Engineer | F4: 30000
A5: Labor Costs | B5: 80 | C5: 80 | E5: Senior Hardware Engineer | F5: 24000
A6: Salary | B6: 132000
A7: Raw Materials | B7: 0 | C7: 0 | E7: Senior Software Engineer | F7: 24000
A8: Operational Costs | E8: Product Manager | F8: 30000
A9: Rent (WFH) | B9: 0 | C9: 0 | E9: Total salary | F9: 132000
A10: Utilities (Electricity, Water, Internet, etc) - WFH | B10: 0 | C10: 0
A11: Technology Licenses (Zoom, Microsoft, GitHub, etc) | B11: 1000 | C11: 1000
A12: Advertising | B12: 200 | C12: 200 | E12: Profit Calculation
A13: Employee WFH office stipends | B13: 170 | C13: 170 | E13: Total Monthly Expenses: Total Monthly Expenses = $200 (Marketing) + $1000 (Technology Licenses) + $200 (Advertising) + $250 (Employee WFH office stipends) + $500 (Insurance, Legal and Administrative Fees) + $1000 (Hardware costs) + $1000 (Travel costs) + $128.93 (Loan Repaying) + $2000 (Future Expansion Capital) + $132,000 (Salary)
A14: Insurance, Legal and Administrative Fees | B14: 500 | C14: 500 | E14: Total Monthly Expenses = $138,078.93
A15: Hardware costs (computers, IT hardware) | B15: 1000 | C15: 1000 | E15: Total Monthly Revenue: Total Monthly Revenue = Total Monthly Expenses + Profit
A16: Travel costs (in person meetings) | B16: 1000 | C16: 1000 | E16: Total Monthly Revenue = $138,078.93 + Profit
A17: Other Costs | E17: Profit: Profit = 10% of Total Monthly Revenue = 0.10 * (Total Monthly Revenue)
A18: Loan Repaying | B18: 128.93 | C18: 128.93 | E18: Profit= 0.10∗138,078.93+0.10∗Profit
A19: Future Expansion Capital | B19: 2000 | C19: 2000 | E19: Profit=13,807.893+0.10∗Profit
A20: Repairs & Replacements | B20: 0 | C20: 0 | E20: 0.90∗Profit=13,807.893
A21: Profit: 10% of Total Monthly Revenue (after deducting all expenses) | B21: 15342 | C21: 15342
A23: Total Product Price | B23: =SUM(B2:B22) -> 158620.93 | C23: =sum(C3:C19) -> 11278.93
E24: Assumptions
A25: Forecast Total Sales Volume (Units) | B25: 1000 | E25: Loan of $20K for 10 years time period; where EMI ≈ $128.93
A26: Total Cost per Unit | B26: =B23/B25 -> 158.62093 | E26: Investor Capital is zero : As a team we have ventured and have fully funded:$ 100k a project with loan of $20k for ongoing expenses
A27: Desired Profit Margin (10%) | B27: 0.1 | E27: Future Expansion Capital: $2,000 (monthly allocation)
A28: Markup Amount | B28: =B26*B27 -> 15.862093 | E28: Salary is sum of amount paid towards the staff ie Sum of Salaries of Blockchain Engineer ,Senior Systems Engineer,Senior Hardware Engineer,Senior Software Engineer,Product Manager
A29: Selling Price (Cost Plus Pricing Model) | B29: =B26+B28 -> 174.48302 | E29: Labor Costs is assumed as zero as it is a software solutions , as we partner with companies for Sensor
A30: Note : Please find all additional assumptions and necessary calculations in the right side of Excel.
A31: Calculating in terms of Gallons of water
A32: Assumption : $1,100 per month for managing 10 million gallons of water.
A33: Volume managed per dollar = 10,000,000 gallons / $1,100 = 8,333.33 gallons per dollar
A34: Now, to estimate the volume of water managed by AquaChain for $174.48: | B34: =B29 -> 174.48302
A35: Volume managed by AquaChain = Volume managed per dollar * Price of AquaChain solution
A36: Volume managed by AquaChain = 8,333.33 gallons per dollar * $174.48 | B36: 1454024.6
A37: Volume managed by AquaChain ≈ 1,454,024.61 gallons
A40: So, based on the updated competitor pricing of $1,200 per 10 million gallons of water, AquaChain competitive pricing of $1100 per 10 million gallons of water could potentially manage approximately 1.45 million gallons of water for a price of $174.48
A42: Competitive comparison
A43: Company | B43: Location | C43: Charging Model | D43: Typical Price Range
A44: AquaChain | B44: Southern California | C44: Subscription-based | D44: ='Income Statement'!C20/4 -> 42245
...

Sheet Balance Sheet
A1: Assets | B1: Year 2024 | C1: Year 2025 | E1: Liabilities and Shareholder's Equity | F1: Year 2024 | G1: Year 2025
A2: Current assets | E2: Current Liabilities
A3: Cash and cash equivalents | B3: 145200 | C3: 150000 | E3: Accounts Payable | F3: 15000 | G3: 12000
A4: Prepaid Expenses | B4: 3000 | C4: 3500 | E4: Salaries Payable | F4: 261780 | G4: 279696
A5: Account receivable | B5: 50000 | C5: 55000 | E5: Taxes Payable | F5: 4420 | G5: 5304
A6: Inventory | B6: 0 | C6: 0 | E6: Accrued Expenses | F6: 3000 | G6: 4500
A7: Total current assets | B7: 198200 | C7: 208500 | E7: Long Term Liabilities | F7: 40000 | G7: 40000
E8: Total Liabilities | F8: =SUM(F3:F7) -> 324200 | G8: =SUM(G3:G7) -> 341500
A9: Fixed assets | E9: Shareholder's Equity
A10: Property, Equipment | B10: 50000 | C10: 55000 | E10: Common Stock | F10: 10000 | G10: 10000
A11: Less depreciation | B11: 9000 | C11: 10000 | E11: Retained earnings | F11: 0 | G11: 0
A12: Intangible assets | E12: Total Shareholder's equity | F12: =SUM(F10:F11) -> 10000 | G12: =SUM(G10:G11) -> 10000
A13: Patents and Trademarks | B13: 100000 | C13: 105000
A14: Less Amortization | B14: 5000 | C14: 7000 | E14: Total Liabilities and Shareholder's Equity | F14: =SUM(F8,F12) -> 334200 | G14: =SUM(G8,G12) -> 351500
A15: Total fixed assets | B15: 136000 | C15: 143000
A16: Total Assets | B16: 334200 | C16: 351500
A18: Note : Please refere reasoning for values in asset table based on market research .
A19: Loan Amount: $20,000 Initial Funding: $100,000 Estimated OCF (Year 1): $25,200 (See previous explanation for OCF estimation) Cash & Cash Equivalents Estimate (Year 1): $20,000 (Loan) + $100,000 (Funding) + $25,200 (OCF) = $145,200
A20: Prepaid Software Licenses (annual): $1,000 Other Prepaid Expenses: $2,000 Total Prepaid Expenses: $1,000 + $2,000 = $3,000
A21: Inventory = $0 for AquaChain in the asset table is because it's a service-based company and uses sensors through tie ups with other company
A22: Year 1 :Total fixed assets = Property, Equipment - Depreciation + Patents and Trademarks - Amortization Total fixed assets = ($50,000 - $9,000) + ($100,000 - $5,000) Total fixed assets = $41,000 + $95,000 Total fixed assets = $136,000
A23: Year 2: Total fixed assets = Property, Equipment - Depreciation + Patents and Trademarks - Amortization Total fixed assets = ($55,000 - $10,000) + ($105,000 - $7,000) Total fixed assets = $45,000 + $98,000 Total fixed assets = $143,000

Sheet Cash Flow Statement
A1: Cash Flow Statement at the end of Year 1
A2: Category | B2: Description | C2: Amount ($) | D2: Comments
A3: Cash Flows from Operating Activities
A4: Salaries | B4: Outflows for team salaries | C4: -150000 | D4: This cost includes salaries for a small to medium-sized team comprising blockchain engineers, systems engineers, hardware engineers, and support staff. The average annual salary for such specialized roles in the tech industry can range from $70,000 to $120,000 or more.
A5: Research and Development | B5: Outflows for R&D expenses | C5: =-('Development Costs Non Recurrent'!H22) -> -366700 | D5: R&D is critical in the initial stages of a tech project. This budget accounts for prototype development, software iteration, testing, and improvements. Industry benchmarks for R&D intensity (R&D expenses as a percentage of sales) in tech sectors can be around 10-15% for established companies, but for startups, it can be much higher, often exceeding 30-50% of the total budget.
A6: Marketing and Sales Promotion | B6: Outflows for marketing activities | C6: -50000 | D6: Early-stage marketing for tech products includes brand development, website creation, digital marketing campaigns, and initial customer outreach.
A7: Office Rent and Utilities | B7: Outflows for office-related expenses | C7: -30000 | D7: Based on commercial real estate data, the average office rent can range from $20 to $50 per square foot per year in urban areas.
A8: Other Operating Expenses | B8: Miscellaneous operating expenses | C8: -20000 | D8: This would cover miscellaneous costs such as office supplies, telecommunications, software subscriptions, and travel.
A9: Net Cash from Operating Activities | C9: =SUM(C4:C8) -> -616700
A11: Cash Flows from Investing Activities
A12: Purchase of Equipment | B12: Outflows for equipment purchases | C12: -40000 | D12: Initial investment in long-term assets such as computers, networking equipment, and other technical hardware for development purposes.
A13: Net Cash from Investing Activities | C13: =SUM(C12) -> -40000
A15: Cash Flows from Financing Activities
A16: Initial Capital Investment | B16: Inflows from investors | C16: ='Balance Sheet'!B3 -> 145200 | D16: Seed funding for startups often ranges from $50,000 to several hundred thousand dollars.
A17: Repayment of Loans | B17: Outflows for loan repayment | C17: -10000 | D17: Repayments on any short-term loans or debts that were incurred for initial setup costs.
A18: Investor Dividends | B18: Outflows for dividends to investors | C18: -5000 | D18: A small dividend payout to early investors
A19: Net Cash from Financing Activities | C19: =SUM(C16:C18) -> 130200
A21: Net Increase (Decrease) in Cash | C21: =SUM(C9,C19) -> -486500 | D21: The net decrease in cash (-$219,800.00) is expected for startups in their first year, reflecting significant upfront investment in product development and market entry activities before generating revenue.
A22: Cash at Beginning of Year | C22: 0
A23: Cash at End of Year | C23: =SUM(C21,C22) -> -486500
A25: =A23 -> Cash at End of Year | B25: =C23 -> -486500 | D25: References
D26: Salaries:
D27: For salary benchmarks PayScale, Glassdoor, or LinkedIn Salary
D28: Research and Development:
D29: The National Science Foundation (NSF) and R&D Magazine publish data and articles on R&D spending trends in various industries.
D30: Marketing and Sales Promotion:
D31: Marketing costs for startups can be researched through marketing agencies' publications or industry reports from sources like HubSpot and the American Marketing Association.
D32: Office Rent and Utilities:
D33: Real estate services like CBRE or JLL offer reports on office rental rates in different cities.
D34: Other Operating Expenses:
D35: General business operation cost data can often be found in business publications such as Forbes and Entrepreneur.
D36: Purchase of Equipment:
D37: For the costs of office equipment, you could look at providers like Dell for computers and networking equipment.
... D43: Investopedia provides a wealth of information on cash flow management and financial statement analysis.

Sheet Income Statement
C1: Year 1 | D1: Year 2 | E1: Year 3 | F1: Year 4 | G1: Year 5 | H1: Year 6 | I1: Year 7 | J1: Year 8 | K1: Year 9 | L1: Year 10
B2: Revenue
B3: Net Sales | C3: ='Sales Forecast'!G3 -> 174480 | D3: ='Sales Forecast'!G4 -> 340236 | E3: ='Sales Forecast'!G5 -> 598815.36 | F3: ='Sales Forecast'!G6 -> 688637.66 | G3: ='Sales Forecast'!G7 -> 1249890.4 | H3: ='Sales Forecast'!$G8 -> 1429969.9 | I3: ='Sales Forecast'!$G9 -> 1584562.6 | J3: ='Sales Forecast'!$G10 -> 1739155.3 | K3: ='Sales Forecast'!$G11 -> 1893748 | L3: ='Sales Forecast'!$G12 -> 2048340.7
B4: Costs of Revenue
B5: Cost of sales | C5: ='Production Costs Recurrent Cost'!C20 -> 140950 | D5: =C5 *1.1 -> 155045 | E5: =D5 *1.1 -> 170549.5 | F5: =E5 *1.1 -> 187604.45 | G5: =F5 *1.1 -> 206364.89 | H5: =G5 *1.1 -> 227001.38 | I5: =H5 *1.1 -> 249701.52 | J5: =I5 *1.1 -> 274671.68 | K5: =J5 *1.1 -> 302138.84 | L5: =K5 *1.1 -> 332352.73
B6: Gross Profit | C6: =C3-C5 -> 33530 | D6: =D3-D5 -> 185191 | E6: =E3-E5 -> 428265.86 | F6: =F3-F5 -> 501033.21 | G6: =G3-G5 -> 1043525.5 | H6: =H3-H5 -> 1202968.5 | I6: =I3-I5 -> 1334861 | J6: =J3-J5 -> 1464483.6 | ... L6: =L3-L5 -> 1715988
B7: Operating Expenses
B8: Research and development | C8: ='Development Costs Non Recurrent'!H22 -> 366700 | D8: =(2/3) *C8 -> 244466.67 | E8: =(1/20)*C8 -> 18335 | F8: =(1/60) *C8 -> 6111.6667 | G8: =(1/120) *C8 -> 3055.8333 | H8: 3000 | I8: 3000 | J8: 3000 | K8: 3000 | L8: 3000
B9: Other operating expenses | C9: ='Pricing Model'!B23 -> 158620.93 | D9: =(1.1) *C9 -> 174483.02 | E9: =(1.1) *D9 -> 191931.33 | F9: =(1.1) *E9 -> 211124.46 | G9: =(1.1) *F9 -> 232236.9 | H9: =(1.1) *G9 -> 255460.59 | I9: =(1.1) *H9 -> 281006.65 | J9: =(1.1) *I9 -> 309107.32 | K9: =(1.1) *J9 -> 340018.05 | L9: =(1.1) *K9 -> 374019.86
B10: Total operating Expenses | C10: =C8+C9 -> 525320.93 | D10: =D8+D9 -> 418949.69 | E10: =E8+E9 -> 210266.33 | F10: =F8+F9 -> 217236.12 | G10: =G8+G9 -> 235292.74 | H10: =H8+H9 -> 258460.59 | I10: =I8+I9 -> 284006.65 | J10: =J8+J9 -> 312107.32 | ... L10: =L8+L9 -> 377019.86
B11: Operating income | C11: =C6-C10 -> -491790.93 | D11: =D6-D10 -> -233758.69 | E11: =E6-E10 -> 217999.53 | F11: =F6-F10 -> 283797.09 | G11: =G6-G10 -> 808232.75 | H11: =H6-H10 -> 944507.88 | I11: =I6-I10 -> 1050854.4 | J11: =J6-J10 -> 1152376.3 | ... L11: =L6-L10 -> 1338968.1
B12: Other Revenue and Expenses
B13: Provision for income taxes | C13: 0 | D13: 0 | E13: =E6 * 0.3 -> 128479.76 | F13: =F6 * 0.3 -> 150309.96 | G13: =G6 * 0.3 -> 313057.65 | H13: =H6 * 0.3 -> 360890.54 | I13: =I6 * 0.3 -> 400458.31 | J13: =J6 * 0.3 -> 439345.08 | K13: =K6 * 0.3 -> 477482.74 | L13: =L6 * 0.3 -> 514796.39
B14: Net Income | C14: =C11-C13 -> -491790.93 | D14: =D11-D13 -> -233758.69 | E14: =E11-E13 -> 89519.777 | F14: =F11-F13 -> 133487.13 | G14: =G11-G13 -> 495175.11 | H14: =H11-H13 -> 583617.34 | I14: =I11-I13 -> 650396.08 | J14: =J11-J13 -> 713031.2 | ... L14: =L11-L13 -> 824171.71
B17: Income Statement
C18: 2024 | D18: 2025 | E18: 2026 | F18: 2027 | G18: 2028 | H18: 2029 | I18: 2030 | J18: 2031 | K18: 2032 | L18: 2033
B19: Revenue
B20: Net Sales | C20: 168980 | D20: 329511 | E20: 579945.6 | F20: 666937.44 | G20: 1204583.1 | H20: 1378134.9 | I20: 1527123.7 | J20: 1676112.6 | K20: 1825101.5 | L20: 1974090.4
B21: Costs of Revenue
B22: Cost of sales | C22: 140950 | D22: 155045 | E22: 170549.5 | F22: 187604.45 | G22: 206364.9 | H22: 227001.38 | I22: 249701.52 | J22: 274671.68 | K22: 302138.84 | L22: 332352.73
B23: Gross Profit | C23: 28030 | D23: 174466 | E23: 409396.1 | F23: 479332.99 | G23: 998218.2 | H23: 1151133.5 | I23: 1277422.2 | J23: 1401440.9 | K23: 1522962.6 | L23: 1641737.6
B24: Operating Expenses
B25: Research and development | C25: 366700 | D25: 244466.67 | E25: 18335 | F25: 6111.6667 | G25: 3055.8333 | H25: 3000 | I25: 3000 | J25: 3000 | K25: 3000 | L25: 3000
B26: Other operating expenses | C26: 153620.93 | D26: 168983.02 | E26: 185881.33 | F26: 204469.46 | G26: 224916.4 | H26: 247408.04 | I26: 272148.85 | J26: 299363.73 | K26: 329300.11 | L26: 362230.12
B27: Total operating Expenses | C27: 520320.93 | D27: 413449.69 | E27: 204216.33 | F27: 210581.12 | G27: 227972.24 | H27: 250408.04 | I27: 275148.85 | J27: 302363.73 | K27: 332300.11 | L27: 365230.12
B28: Operating income | C28: -492290.93 | D28: -238983.69 | E28: 205179.77 | F28: 268751.87 | G28: 770245.96 | H28: 900725.44 | I28: 1002273.4 | J28: 1099077.2 | K28: 1190662.5 | L28: 1276507.5
B29: Other Revenue and Expenses
B30: Provision for income taxes | C30: 0 | D30: 0 | E30: 122818.83 | F30: 143799.9 | G30: 299465.46 | H30: 345340.04 | I30: 383226.66 | J30: 420432.28 | K30: 456888.79 | L30: 492521.29
B31: Net Income | C31: -492290.93 | D31: -238983.69 | E31: 82360.945 | F31: 124951.97 | G31: 470780.5 | H31: 555385.39 | I31: 619046.7 | J31: 678644.92 | K31: 733773.74 | L31: 783986.22
K34: Total revenue | L34: =SUM(C20:L20) -> 11330520
K35: Margin | L35: ='Capital Budgeting Analysis'!L5/L34 -> 0.31198542

Sheet Valuation Model
A1: Valuation Model
A3: Line item | B3: 2024 - 2033
A4: Revenue | B4: =SUM('Income Statement'!C3:L3) -> 11747836
A5: EBITDA | B5: =SUM('Income Statement'!C11:L11) -> 6319777.5
A6: EBITDA % | B6: =B5/B4 -> 0.53795249
A8: EBITDA Multiple | B8: 12.67
A9: Enterprise Value | B9: =B8*B5 -> 80071581
A11: Total Debt | B11: 2400000
A13: Plus: Total Cash | B13: 500000
A15: Equity Value | B15: =B9-B11+B13 -> 78171581
A19: Valuation Model
A21: Line item | B21: 2024 - 2033
A22: Revenue | B22: 11330520
A23: EBITDA | B23: 5982149
A24: EBITDA % | B24: 0.52796773
A26: EBITDA Multiple | B26: 12.67
A27: Enterprise Value | B27: 75793828
A29: Total Debt | B29: 2400000
A31: Plus: Total Cash | B31: 500000
A33: Equity Value | B33: 73893828
A36: Actual Investment percentage | B36: =(100/B15)*'Cash Flow Statement'!C16 -> 0.18574525
A37: Ask | B37: 5
A38: Value that we actually give away | B38: =(B15/100)*B37 -> 3908579
A39: Value in case of Investor Negotiation | B39: =('Cash Flow Statement'!C16/B37)*100 -> 2904000
A40: ROI | B40: ='Capital Budgeting Analysis'!L5/B39 -> 1.2172717

Sheet Capital Budgeting Analysis
B2: Capital Budgeting Analysis
B3: Year | C3: 0 | D3: 1 | E3: 2 | F3: 3 | G3: 4 | H3: 5 | I3: 6 | J3: 7 | K3: 8 | L3: 9
B4: NCF | C4: ='Income Statement'!C14 -> -491790.93 | D4: ='Income Statement'!D14 -> -233758.69 | E4: ='Income Statement'!E14 -> 89519.777 | F4: ='Income Statement'!F14 -> 133487.13 | G4: ='Income Statement'!G14 -> 495175.11 | H4: ='Income Statement'!H14 -> 583617.34 | I4: ='Income Statement'!I14 -> 650396.08 | J4: ='Income Statement'!J14 -> 713031.2 | ... L4: ='Income Statement'!L14 -> 824171.71
B5: Cum. NCF | C5: ='Income Statement'!C14 -> -491790.93 | D5: =C5+D4 -> -725549.62 | E5: =D5+E4 -> -636029.84 | F5: =E5+F4 -> -502542.72 | G5: =F5+G4 -> -7367.6119 | H5: =G5+H4 -> 576249.73 | I5: =H5+I4 -> 1226645.8 | J5: =I5+J4 -> 1939677 | K5: =J5+K4 -> 2710785.3 | L5: =K5+L4 -> 3534957.1
B6: NPV | C6: {=NPV(C7, E4:L4)+C4+D4} -> 1823317.8 | G6: IRR | H6: =IRR(C4:L4) -> 0.36446672
B7: Discount Rate | C7: 0.1
B8: Discounted NCF | C8: =C4/((1+$C$7)^C3) -> -491790.93 | D8: =D4/((1+$C$7)^D3) -> -212507.9 | E8: =E4/((1+$C$7)^E3) -> 73983.287 | F8: =F4/((1+$C$7)^F3) -> 100290.85 | G8: =G4/((1+$C$7)^G3) -> 338211.26 | H8: =H4/((1+$C$7)^H3) -> 362380.45 | I8: =I4/((1+$C$7)^I3) -> 367131.63 | J8: =J4/((1+$C$7)^J3) -> 365897.75 | ... L8: =L4/((1+$C$7)^L3) -> 349529.26
B9: Cumulative D. NCF | C9: =C8 -> -491790.93 | D9: =C9+D8 -> -704298.83 | E9: =D9+E8 -> -630315.54 | F9: =E9+F8 -> -530024.69 | G9: =F9+G8 -> -191813.43 | H9: =G9+H8 -> 170567.02 | I9: =H9+I8 -> 537698.65 | J9: =I9+J8 -> 903596.4 | K9: =J9+K8 -> 1263324.1 | L9: =K9+L8 -> 1612853.4
B10: NPV
B11: IRR
B12: ROI

Sheet Investment Spending
A1: Hiring for R&D | B1: 0.7 | C1: Refer Non-recurring costs
A2: Infrastructure for Testing | B2: 0.28 | C2: Refer Production costs
A3: Miscellaneous Legal, Business, Finance audit consultation | B3: 0.02
